Workbook

Sheet Тема урока
A32: 1
A66: 1
A99: 1

Sheet Выполнить
F2: id_cmpgn | G2: partners | H2: транзакции | I2: groups | AY2: id_cmpgn | BA2: partners | BC2: транзакции | BD2: group
F3: 615eaaebbc6c | G3: =VLOOKUP(VLOOKUP($F3,Отчет!$F$4:$K$603,2,FALSE),Партнеры!$F$4:$G$53,2,FALSE) -> FinTech Hub | H3: =VLOOKUP($F3,Отчет!$F$4:$K$603,6,FALSE) -> 2518 | I3: =HLOOKUP($H3,Отчет!$N$3:$R$4,2,TRUE) -> 2,5к и более | AY3: 615eaaebbc6c | AZ3: =VLOOKUP(AY3,Отчет!$F:$G,2,0) -> prtr9jqee | BA3: =VLOOKUP(VLOOKUP(AY3,Отчет!$F:$G,2,0),Партнеры!$F:$G,2,0) -> FinTech Hub | BB3: =VLOOKUP(AZ3,Партнеры!$F:$G,2,0) -> FinTech Hub | BC3: =VLOOKUP(AY3,Отчет!$F:$K,6,0) -> 2518 | BD3: =HLOOKUP(BC3,Отчет!$N$3:$R$4,2,1) -> 2,5к и более
F4: 94e0f0bda838 | G4: =VLOOKUP(VLOOKUP($F4,Отчет!$F$4:$K$603,2,FALSE),Партнеры!$F$4:$G$53,2,FALSE) -> SmartCommerce Lab | H4: =VLOOKUP($F4,Отчет!$F$4:$K$603,6,FALSE) -> 1216 | I4: =HLOOKUP($H4,Отчет!$N$3:$R$4,2,TRUE) -> 1-1,5к | AY4: 94e0f0bda838 | AZ4: =VLOOKUP(AY4,Отчет!$F:$G,2,0) -> prtrcbe4z | BA4: =VLOOKUP(VLOOKUP(AY4,Отчет!$F:$G,2,0),Партнеры!$F:$G,2,0) -> SmartCommerce Lab | BB4: =VLOOKUP(AZ4,Партнеры!$F:$G,2,0) -> SmartCommerce Lab | BC4: =VLOOKUP(AY4,Отчет!$F:$K,6,0) -> 1216 | BD4: =HLOOKUP(BC4,Отчет!$N$3:$R$4,2,1) -> 1-1,5к
F5: 5c326aa4ed36 | G5: =VLOOKUP(VLOOKUP($F5,Отчет!$F$4:$K$603,2,FALSE),Партнеры!$F$4:$G$53,2,FALSE) -> EcomConnect Partners (ECP) | H5: =VLOOKUP($F5,Отчет!$F$4:$K$603,6,FALSE) -> 2908 | I5: =HLOOKUP($H5,Отчет!$N$3:$R$4,2,TRUE) -> 2,5к и более | AY5: 5c326aa4ed36 | AZ5: =VLOOKUP(AY5,Отчет!$F:$G,2,0) -> prtru0tfb | BA5: =VLOOKUP(VLOOKUP(AY5,Отчет!$F:$G,2,0),Партнеры!$F:$G,2,0) -> EcomConnect Partners (ECP) | BB5: =VLOOKUP(AZ5,Партнеры!$F:$G,2,0) -> EcomConnect Partners (ECP) | BC5: =VLOOKUP(AY5,Отчет!$F:$K,6,0) -> 2908 | BD5: =HLOOKUP(BC5,Отчет!$N$3:$R$4,2,1) -> 2,5к и более
F6: 48c493b28756 | G6: =VLOOKUP(VLOOKUP($F6,Отчет!$F$4:$K$603,2,FALSE),Партнеры!$F$4:$G$53,2,FALSE) -> Evolve Commerce | H6: =VLOOKUP($F6,Отчет!$F$4:$K$603,6,FALSE) -> 174 | I6: =HLOOKUP($H6,Отчет!$N$3:$R$4,2,TRUE) -> 0-500 | AY6: 48c493b28756 | AZ6: =VLOOKUP(AY6,Отчет!$F:$G,2,0) -> prtrx3a6r | BA6: =VLOOKUP(VLOOKUP(AY6,Отчет!$F:$G,2,0),Партнеры!$F:$G,2,0) -> Evolve Commerce | BB6: =VLOOKUP(AZ6,Партнеры!$F:$G,2,0) -> Evolve Commerce | BC6: =VLOOKUP(AY6,Отчет!$F:$K,6,0) -> 174 | BD6: =HLOOKUP(BC6,Отчет!$N$3:$R$4,2,1) -> 0-500
F7: 56f173290545 | G7: =VLOOKUP(VLOOKUP($F7,Отчет!$F$4:$K$603,2,FALSE),Партнеры!$F$4:$G$53,2,FALSE) -> TechFin Studio | H7: =VLOOKUP($F7,Отчет!$F$4:$K$603,6,FALSE) -> 29 | I7: =HLOOKUP($H7,Отчет!$N$3:$R$4,2,TRUE) -> 0-500 | AY7: 56f173290545 | AZ7: =VLOOKUP(AY7,Отчет!$F:$G,2,0) -> prtrxih4w | BA7: =VLOOKUP(VLOOKUP(AY7,Отчет!$F:$G,2,0),Партнеры!$F:$G,2,0) -> TechFin Studio | BB7: =VLOOKUP(AZ7,Партнеры!$F:$G,2,0) -> TechFin Studio | BC7: =VLOOKUP(AY7,Отчет!$F:$K,6,0) -> 29 | BD7: =HLOOKUP(BC7,Отчет!$N$3:$R$4,2,1) -> 0-500
F8: 94558eb1b0c3 | G8: =VLOOKUP(VLOOKUP($F8,Отчет!$F$4:$K$603,2,FALSE),Партнеры!$F$4:$G$53,2,FALSE) -> FinFlow Technologies | H8: =VLOOKUP($F8,Отчет!$F$4:$K$603,6,FALSE) -> 1526 | I8: =HLOOKUP($H8,Отчет!$N$3:$R$4,2,TRUE) -> 1,5-2,5к | AY8: 94558eb1b0c3 | AZ8: =VLOOKUP(AY8,Отчет!$F:$G,2,0) -> prtrbmh6t | BA8: =VLOOKUP(VLOOKUP(AY8,Отчет!$F:$G,2,0),Партнеры!$F:$G,2,0) -> FinFlow Technologies | BB8: =VLOOKUP(AZ8,Партнеры!$F:$G,2,0) -> FinFlow Technologies | BC8: =VLOOKUP(AY8,Отчет!$F:$K,6,0) -> 1526 | BD8: =HLOOKUP(BC8,Отчет!$N$3:$R$4,2,1) -> 1,5-2,5к
F9: 82f74e867bba | G9: =VLOOKUP(VLOOKUP($F9,Отчет!$F$4:$K$603,2,FALSE),Партнеры!$F$4:$G$53,2,FALSE) -> EcomConnect Partners (ECP) | H9: =VLOOKUP($F9,Отчет!$F$4:$K$603,6,FALSE) -> 2749 | I9: =HLOOKUP($H9,Отчет!$N$3:$R$4,2,TRUE) -> 2,5к и более | AY9: 82f74e867bba | AZ9: =VLOOKUP(AY9,Отчет!$F:$G,2,0) -> prtru0tfb | BA9: =VLOOKUP(VLOOKUP(AY9,Отчет!$F:$G,2,0),Партнеры!$F:$G,2,0) -> EcomConnect Partners (ECP) | BB9: =VLOOKUP(AZ9,Партнеры!$F:$G,2,0) -> EcomConnect Partners (ECP) | BC9: =VLOOKUP(AY9,Отчет!$F:$K,6,0) -> 2749 | BD9: =HLOOKUP(BC9,Отчет!$N$3:$R$4,2,1) -> 2,5к и более
F10: b68cbb85a342 | G10: =VLOOKUP(VLOOKUP($F10,Отчет!$F$4:$K$603,2,FALSE),Партнеры!$F$4:$G$53,2,FALSE) -> EcomTrail Partners | H10: =VLOOKUP($F10,Отчет!$F$4:$K$603,6,FALSE) -> 2161 | I10: =HLOOKUP($H10,Отчет!$N$3:$R$4,2,TRUE) -> 1,5-2,5к | AY10: b68cbb85a342 | AZ10: =VLOOKUP(AY10,Отчет!$F:$G,2,0) -> prtr00z3s | BA10: =VLOOKUP(VLOOKUP(AY10,Отчет!$F:$G,2,0),Партнеры!$F:$G,2,0) -> EcomTrail Partners | BB10: =VLOOKUP(AZ10,Партнеры!$F:$G,2,0) -> EcomTrail Partners | BC10: =VLOOKUP(AY10,Отчет!$F:$K,6,0) -> 2161 | BD10: =HLOOKUP(BC10,Отчет!$N$3:$R$4,2,1) -> 1,5-2,5к
F11: 078d4fa15ab6 | G11: =VLOOKUP(VLOOKUP($F11,Отчет!$F$4:$K$603,2,FALSE),Партнеры!$F$4:$G$53,2,FALSE) -> FinTech Hub | H11: =VLOOKUP($F11,Отчет!$F$4:$K$603,6,FALSE) -> 2316 | I11: =HLOOKUP($H11,Отчет!$N$3:$R$4,2,TRUE) -> 1,5-2,5к | AY11: 078d4fa15ab6 | AZ11: =VLOOKUP(AY11,Отчет!$F:$G,2,0) -> prtr9jqee | BA11: =VLOOKUP(VLOOKUP(AY11,Отчет!$F:$G,2,0),Партнеры!$F:$G,2,0) -> FinTech Hub | BB11: =VLOOKUP(AZ11,Партнеры!$F:$G,2,0) -> FinTech Hub | BC11: =VLOOKUP(AY11,Отчет!$F:$K,6,0) -> 2316 | BD11: =HLOOKUP(BC11,Отчет!$N$3:$R$4,2,1) -> 1,5-2,5к
F12: 0c17bea25098 | G12: =VLOOKUP(VLOOKUP($F12,Отчет!$F$4:$K$603,2,FALSE),Партнеры!$F$4:$G$53,2,FALSE) -> SmartCommerce Lab | H12: =VLOOKUP($F12,Отчет!$F$4:$K$603,6,FALSE) -> 1834 | I12: =HLOOKUP($H12,Отчет!$N$3:$R$4,2,TRUE) -> 1,5-2,5к | AY12: 0c17bea25098 | AZ12: =VLOOKUP(AY12,Отчет!$F:$G,2,0) -> prtrcbe4z | BA12: =VLOOKUP(VLOOKUP(AY12,Отчет!$F:$G,2,0),Партнеры!$F:$G,2,0) -> SmartCommerce Lab | BB12: =VLOOKUP(AZ12,Партнеры!$F:$G,2,0) -> SmartCommerce Lab | BC12: =VLOOKUP(AY12,Отчет!$F:$K,6,0) -> 1834 | BD12: =HLOOKUP(BC12,Отчет!$N$3:$R$4,2,1) -> 1,5-2,5к
F13: 7343e3387885 | G13: =VLOOKUP(VLOOKUP($F13,Отчет!$F$4:$K$603,2,FALSE),Партнеры!$F$4:$G$53,2,FALSE) -> Marketology Experts (MEX) | H13: =VLOOKUP($F13,Отчет!$F$4:$K$603,6,FALSE) -> 3544 | I13: =HLOOKUP($H13,Отчет!$N$3:$R$4,2,TRUE) -> 2,5к и более | AY13: 7343e3387885 | AZ13: =VLOOKUP(AY13,Отчет!$F:$G,2,0) -> prtrjzevz | BA13: =VLOOKUP(VLOOKUP(AY13,Отчет!$F:$G,2,0),Партнеры!$F:$G,2,0) -> Marketology Experts (MEX) | BB13: =VLOOKUP(AZ13,Партнеры!$F:$G,2,0) -> Marketology Experts (MEX) | BC13: =VLOOKUP(AY13,Отчет!$F:$K,6,0) -> 3544 | BD13: =HLOOKUP(BC13,Отчет!$N$3:$R$4,2,1) -> 2,5к и более
F14: 4db79e788509 | G14: =VLOOKUP(VLOOKUP($F14,Отчет!$F$4:$K$603,2,FALSE),Партнеры!$F$4:$G$53,2,FALSE) -> EcomConnect Partners (ECP) | H14: =VLOOKUP($F14,Отчет!$F$4:$K$603,6,FALSE) -> 501 | I14: =HLOOKUP($H14,Отчет!$N$3:$R$4,2,TRUE) -> 500-1к | AY14: 4db79e788509 | AZ14: =VLOOKUP(AY14,Отчет!$F:$G,2,0) -> prtru0tfb | BA14: =VLOOKUP(VLOOKUP(AY14,Отчет!$F:$G,2,0),Партнеры!$F:$G,2,0) -> EcomConnect Partners (ECP) | BB14: =VLOOKUP(AZ14,Партнеры!$F:$G,2,0) -> EcomConnect Partners (ECP) | BC14: =VLOOKUP(AY14,Отчет!$F:$K,6,0) -> 501 | BD14: =HLOOKUP(BC14,Отчет!$N$3:$R$4,2,1) -> 500-1к
... F32: 50904ff0ee30 | G32: =VLOOKUP(VLOOKUP($F32,Отчет!$F$4:$K$603,2,FALSE),Партнеры!$F$4:$G$53,2,FALSE) -> FinGo Analytics | H32: =VLOOKUP($F32,Отчет!$F$4:$K$603,6,FALSE) -> 2154 | I32: =HLOOKUP($H32,Отчет!$N$3:$R$4,2,TRUE) -> 1,5-2,5к | AY32: 50904ff0ee30 | AZ32: =VLOOKUP(AY32,Отчет!$F:$G,2,0) -> prtrsyyx1 | BA32: =VLOOKUP(VLOOKUP(AY32,Отчет!$F:$G,2,0),Партнеры!$F:$G,2,0) -> FinGo Analytics | BB32: =VLOOKUP(AZ32,Партнеры!$F:$G,2,0) -> FinGo Analytics | BC32: =VLOOKUP(AY32,Отчет!$F:$K,6,0) -> 2154 | BD32: =HLOOKUP(BC32,Отчет!$N$3:$R$4,2,1) -> 1,5-2,5к

Sheet Партнеры
F3: id | G3: partners
F4: prtrjg8mf | G4: EcomMark Solutions
F5: prtr9jqee | G5: FinTech Hub
F6: prtr5veu2 | G6: Marketplace Boosters
F7: prtrczb25 | G7: EcomFlow Agency
F8: prtrmec8l | G8: FinGrow Analytics
F9: prtrjzevz | G9: Marketology Experts (MEX)
F10: prtrw46hw | G10: SmartPay Systems (SPS)
F11: prtrx3a6r | G11: Evolve Commerce
F12: prtr2fs62 | G12: DataFin Marketers (DFM)
F13: prtrvgnnm | G13: EcomTech Ventures
F14: prtrpfaf0 | G14: MarketUp Pro
... F53: prtr4p7x8 | G53: PayWave Solutions

Sheet Отчет
F3: id_cmpgn | G3: id_prtr | H3: месяц | I3: просмотры | J3: клики | K3: транзакции | M3: Counts | N3: 0 | O3: 501 | P3: 1001 | Q3: 1501 | R3: 2501 | AW3: id_cmpgn | AX3: partners | AY3: транзакции | AZ3: groups | BB3: id | BC3: partners | BF3: id_cmpgn | BG3: месяц | BH3: просмотры | BI3: клики | BJ3: id_prtr | BK3: транзакции | BS3: id_prtr | BT3: просмотры | BU3: клики | BV3: транзакции
E4: 1 | F4: 7536deca309a | G4: prtrjg8mf | H4: Январь | I4: 148483 | J4: 33258 | K4: 2834 | M4: Groups | N4: 0-500 | O4: 500-1к | P4: 1-1,5к | Q4: 1,5-2,5к | R4: 2,5к и более | AW4: 615eaaebbc6c | AX4: =VLOOKUP(VLOOKUP(AW4,CHOOSE({1,2},BF:BF,BJ:BJ),2,0),BB:BC,2,0) -> FinTech Hub | BB4: prtrjg8mf | BC4: EcomMark Solutions | BE4: 1 | BF4: 7536deca309a | BG4: Январь | BH4: 148483 | BI4: 33258 | BJ4: prtrjg8mf | BK4: 2834 | BR4: 1 | BS4: prtrjg8mf | BT4: 148483 | BU4: 33258 | BV4: 2834 | BW4: =IF(BS4=$CA$12,COUNTIF($BS$4:BS4,$CA$12),"")
E5: 2 | F5: d1aaa9bf0482 | G5: prtrjg8mf | H5: Февраль | I5: 38241 | J5: 8823 | K5: 813 | AW5: 94e0f0bda838 | AX5: =VLOOKUP(VLOOKUP(AW5,CHOOSE({1,2},BF:BF,BJ:BJ),2,0),BB:BC,2,0) -> SmartCommerce Lab | BB5: prtr9jqee | BC5: FinTech Hub | BE5: 2 | BF5: d1aaa9bf0482 | BG5: Февраль | BH5: 38241 | BI5: 8823 | BJ5: prtrjg8mf | BK5: 813 | BR5: 2 | BS5: prtrjg8mf | BT5: 38241 | BU5: 8823 | BV5: 813 | BW5: =IF(BS5=$CA$12,COUNTIF($BS$4:BS5,$CA$12),"")
E6: 3 | F6: 96afc95efd12 | G6: prtrjg8mf | H6: Март | I6: 54157 | J6: 11297 | K6: 711 | AW6: 5c326aa4ed36 | AX6: =VLOOKUP(VLOOKUP(AW6,CHOOSE({1,2},BF:BF,BJ:BJ),2,0),BB:BC,2,0) -> EcomConnect Partners (ECP) | BB6: prtr5veu2 | BC6: Marketplace Boosters | BE6: 3 | BF6: 96afc95efd12 | BG6: Март | BH6: 54157 | BI6: 11297 | BJ6: prtrjg8mf | BK6: 711 | BR6: 3 | BS6: prtrjg8mf | BT6: 54157 | BU6: 11297 | BV6: 711 | BW6: =IF(BS6=$CA$12,COUNTIF($BS$4:BS6,$CA$12),"")
E7: 4 | F7: e9833306f49b | G7: prtrjg8mf | H7: Апрель | I7: 22200 | J7: 6717 | K7: 392 | AW7: 48c493b28756 | AX7: =VLOOKUP(VLOOKUP(AW7,CHOOSE({1,2},BF:BF,BJ:BJ),2,0),BB:BC,2,0) -> Evolve Commerce | BB7: prtrczb25 | BC7: EcomFlow Agency | BE7: 4 | BF7: e9833306f49b | BG7: Апрель | BH7: 22200 | BI7: 6717 | BJ7: prtrjg8mf | BK7: 392 | BR7: 4 | BS7: prtrjg8mf | BT7: 22200 | BU7: 6717 | BV7: 392 | BW7: =IF(BS7=$CA$12,COUNTIF($BS$4:BS7,$CA$12),"")
E8: 5 | F8: f3df42649379 | G8: prtrjg8mf | H8: Май | I8: 138053 | J8: 53787 | K8: 2795 | AW8: 56f173290545 | AX8: =VLOOKUP(VLOOKUP(AW8,CHOOSE({1,2},BF:BF,BJ:BJ),2,0),BB:BC,2,0) -> TechFin Studio | BB8: prtrmec8l | BC8: FinGrow Analytics | BE8: 5 | BF8: f3df42649379 | BG8: Май | BH8: 138053 | BI8: 53787 | BJ8: prtrjg8mf | BK8: 2795 | BR8: 5 | BS8: prtrjg8mf | BT8: 138053 | BU8: 53787 | BV8: 2795 | BW8: =IF(BS8=$CA$12,COUNTIF($BS$4:BS8,$CA$12),"")
E9: 6 | F9: fea36b22c7f4 | G9: prtrjg8mf | H9: Июнь | I9: 47567 | J9: 18717 | K9: 1418 | AW9: 94558eb1b0c3 | AX9: =VLOOKUP(VLOOKUP(AW9,CHOOSE({1,2},BF:BF,BJ:BJ),2,0),BB:BC,2,0) -> FinFlow Technologies | BB9: prtrjzevz | BC9: Marketology Experts (MEX) | BE9: 6 | BF9: fea36b22c7f4 | BG9: Июнь | BH9: 47567 | BI9: 18717 | BJ9: prtrjg8mf | BK9: 1418 | BR9: 6 | BS9: prtrjg8mf | BT9: 47567 | BU9: 18717 | BV9: 1418 | BW9: =IF(BS9=$CA$12,COUNTIF($BS$4:BS9,$CA$12),"")
E10: 7 | F10: 39fe9812bfb2 | G10: prtrjg8mf | H10: Июль | I10: 110416 | J10: 33701 | K10: 3266 | AW10: 82f74e867bba | AX10: =VLOOKUP(VLOOKUP(AW10,CHOOSE({1,2},BF:BF,BJ:BJ),2,0),BB:BC,2,0) -> EcomConnect Partners (ECP) | BB10: prtrw46hw | BC10: SmartPay Systems (SPS) | BE10: 7 | BF10: 39fe9812bfb2 | BG10: Июль | BH10: 110416 | BI10: 33701 | BJ10: prtrjg8mf | BK10: 3266 | BR10: 7 | BS10: prtrjg8mf | BT10: 110416 | BU10: 33701 | BV10: 3266 | BW10: =IF(BS10=$CA$12,COUNTIF($BS$4:BS10,$CA$12),"")
E11: 8 | F11: 26b9f2986f37 | G11: prtrjg8mf | H11: Август | I11: 129454 | J11: 30877 | K11: 1029 | AW11: b68cbb85a342 | AX11: =VLOOKUP(VLOOKUP(AW11,CHOOSE({1,2},BF:BF,BJ:BJ),2,0),BB:BC,2,0) -> EcomTrail Partners | BB11: prtrx3a6r | BC11: Evolve Commerce | BE11: 8 | BF11: 26b9f2986f37 | BG11: Август | BH11: 129454 | BI11: 30877 | BJ11: prtrjg8mf | BK11: 1029 | BR11: 8 | BS11: prtrjg8mf | BT11: 129454 | BU11: 30877 | BV11: 1029 | BW11: =IF(BS11=$CA$12,COUNTIF($BS$4:BS11,$CA$12),"") | CA11: prtrjg8mf | CB11: =VLOOKUP(CA11,BS:BV,4,0) -> 2834 | CC11: =INDEX(BV:BV,MATCH(CA11,BS:BS,0)) -> 2834 | CD11: =INDEX(BV:BV,MATCH(5,BW:BW,0)) -> 256 | CE11: {=INDEX(_xlfn._xlws.FILTER(BV:BV,BS:BS=CA11),5)} -> 2795
E12: 9 | F12: 7cfcb4c3115e | G12: prtrjg8mf | H12: Сентябрь | I12: 109685 | J12: 40483 | K12: 3520 | AW12: 078d4fa15ab6 | AX12: =VLOOKUP(VLOOKUP(AW12,CHOOSE({1,2},BF:BF,BJ:BJ),2,0),BB:BC,2,0) -> FinTech Hub | BB12: prtr2fs62 | BC12: DataFin Marketers (DFM) | BE12: 9 | BF12: 7cfcb4c3115e | BG12: Сентябрь | BH12: 109685 | BI12: 40483 | BJ12: prtrjg8mf | BK12: 3520 | BR12: 9 | BS12: prtrjg8mf | BT12: 109685 | BU12: 40483 | BV12: 3520 | BW12: =IF(BS12=$CA$12,COUNTIF($BS$4:BS12,$CA$12),"") | CA12: prtr9jqee | CB12: =VLOOKUP(CA12,BS:BV,4,0) -> 2518 | CC12: =INDEX(BV:BV,MATCH(CA12,BS:BS,0)) -> 2518 | CD12: =INDEX(BV:BV,MATCH(5,BW:BW,0)) -> 256 | CE12: {=INDEX(_xlfn._xlws.FILTER(BV:BV,BS:BS=CA12),5)} -> 256
E13: 10 | F13: 81e231fccb15 | G13: prtrjg8mf | H13: Октябрь | I13: 134341 | J13: 44339 | K13: 1025 | AW13: 0c17bea25098 | AX13: =VLOOKUP(VLOOKUP(AW13,CHOOSE({1,2},BF:BF,BJ:BJ),2,0),BB:BC,2,0) -> SmartCommerce Lab | BB13: prtrvgnnm | BC13: EcomTech Ventures | BE13: 10 | BF13: 81e231fccb15 | BG13: Октябрь | BH13: 134341 | BI13: 44339 | BJ13: prtrjg8mf | BK13: 1025 | BR13: 10 | BS13: prtrjg8mf | BT13: 134341 | BU13: 44339 | BV13: 1025 | BW13: =IF(BS13=$CA$12,COUNTIF($BS$4:BS13,$CA$12),"")
E14: 11 | F14: 44026375c796 | G14: prtrjg8mf | H14: Ноябрь | I14: 18425 | J14: 4724 | K14: 36 | AW14: 7343e3387885 | AX14: =VLOOKUP(VLOOKUP(AW14,CHOOSE({1,2},BF:BF,BJ:BJ),2,0),BB:BC,2,0) -> Marketology Experts (MEX) | BB14: prtrpfaf0 | BC14: MarketUp Pro | BE14: 11 | BF14: 44026375c796 | BG14: Ноябрь | BH14: 18425 | BI14: 4724 | BJ14: prtrjg8mf | BK14: 36 | BR14: 11 | BS14: prtrjg8mf | BT14: 18425 | BU14: 4724 | BV14: 36 | BW14: =IF(BS14=$CA$12,COUNTIF($BS$4:BS14,$CA$12),"")
E15: 12 | F15: 5fe6b74bb508 | G15: prtrjg8mf | H15: Декабрь | I15: 142027 | J15: 42175 | K15: 2193 | AW15: 4db79e788509 | AX15: =VLOOKUP(VLOOKUP(AW15,CHOOSE({1,2},BF:BF,BJ:BJ),2,0),BB:BC,2,0) -> EcomConnect Partners (ECP) | BB15: prtr99kmo | BC15: FinEdge Solutions (FES) | BE15: 12 | BF15: 5fe6b74bb508 | BG15: Декабрь | BH15: 142027 | BI15: 42175 | BJ15: prtrjg8mf | BK15: 2193 | BR15: 12 | BS15: prtrjg8mf | BT15: 142027 | BU15: 42175 | BV15: 2193 | BW15: =IF(BS15=$CA$12,COUNTIF($BS$4:BS15,$CA$12),"")
E16: 13 | F16: 615eaaebbc6c | G16: prtr9jqee | H16: Январь | I16: 110170 | J16: 36391 | K16: 2518 | AW16: f04634dcea1e | AX16: =VLOOKUP(VLOOKUP(AW16,CHOOSE({1,2},BF:BF,BJ:BJ),2,0),BB:BC,2,0) -> PrimeMarketplace | BB16: prtri0a5u | BC16: OmniBoost Commerce | BE16: 13 | BF16: 615eaaebbc6c | BG16: Январь | BH16: 110170 | BI16: 36391 | BJ16: prtr9jqee | BK16: 2518 | BR16: 13 | BS16: prtr9jqee | BT16: 110170 | BU16: 36391 | BV16: 2518 | BW16: =IF(BS16=$CA$12,COUNTIF($BS$4:BS16,$CA$12),"") -> 1
E17: 14 | F17: ff9070b12c6f | G17: prtr9jqee | H17: Февраль | I17: 98498 | J17: 33414 | K17: 1572 | AW17: 315690f55c1c | AX17: =VLOOKUP(VLOOKUP(AW17,CHOOSE({1,2},BF:BF,BJ:BJ),2,0),BB:BC,2,0) -> Marketplace Synergy | BB17: prtrijxhk | BC17: PayFlex Systems (PFS) | BE17: 14 | BF17: ff9070b12c6f | BG17: Февраль | BH17: 98498 | BI17: 33414 | BJ17: prtr9jqee | BK17: 1572 | BR17: 14 | BS17: prtr9jqee | BT17: 98498 | BU17: 33414 | BV17: 1572 | BW17: =IF(BS17=$CA$12,COUNTIF($BS$4:BS17,$CA$12),"") -> 2
E18: 15 | F18: b27746d730de | G18: prtr9jqee | H18: Март | I18: 86199 | J18: 26042 | K18: 70 | AW18: 15791816d56e | AX18: =VLOOKUP(VLOOKUP(AW18,CHOOSE({1,2},BF:BF,BJ:BJ),2,0),BB:BC,2,0) -> SmartCommerce Lab | BB18: prtru1gpg | BC18: NextGen Marketplace | BE18: 15 | BF18: b27746d730de | BG18: Март | BH18: 86199 | BI18: 26042 | BJ18: prtr9jqee | BK18: 70 | BR18: 15 | BS18: prtr9jqee | BT18: 86199 | BU18: 26042 | BV18: 70 | BW18: =IF(BS18=$CA$12,COUNTIF($BS$4:BS18,$CA$12),"") -> 3
E19: 16 | F19: 078d4fa15ab6 | G19: prtr9jqee | H19: Апрель | I19: 131527 | J19: 40252 | K19: 2316 | AW19: d870d66ed71d | AX19: =VLOOKUP(VLOOKUP(AW19,CHOOSE({1,2},BF:BF,BJ:BJ),2,0),BB:BC,2,0) -> FinOptim Strategies | BB19: prtr7q54o | BC19: FinOptim Strategies | BE19: 16 | BF19: 078d4fa15ab6 | BG19: Апрель | BH19: 131527 | BI19: 40252 | BJ19: prtr9jqee | BK19: 2316 | BR19: 16 | BS19: prtr9jqee | BT19: 131527 | BU19: 40252 | BV19: 2316 | BW19: =IF(BS19=$CA$12,COUNTIF($BS$4:BS19,$CA$12),"") -> 4
E20: 17 | F20: 8814b359d5d8 | G20: prtr9jqee | H20: Май | I20: 13856 | J20: 5067 | K20: 256 | AW20: 66ff1cc19d1b | AX20: =VLOOKUP(VLOOKUP(AW20,CHOOSE({1,2},BF:BF,BJ:BJ),2,0),BB:BC,2,0) -> FinScale Strategies | BB20: prtrbndgy | BC20: EcomSync Studio (ESS) | BE20: 17 | BF20: 8814b359d5d8 | BG20: Май | BH20: 13856 | BI20: 5067 | BJ20: prtr9jqee | BK20: 256 | BR20: 17 | BS20: prtr9jqee | BT20: 13856 | BU20: 5067 | BV20: 256 | BW20: =IF(BS20=$CA$12,COUNTIF($BS$4:BS20,$CA$12),"") -> 5
E21: 18 | F21: bd5855a49924 | G21: prtr9jqee | H21: Июнь | I21: 148972 | J21: 54539 | K21: 684 | AW21: 9e19c4a14337 | AX21: =VLOOKUP(VLOOKUP(AW21,CHOOSE({1,2},BF:BF,BJ:BJ),2,0),BB:BC,2,0) -> FinGo Analytics | BB21: prtrgokwu | BC21: Market360 Labs | BE21: 18 | BF21: bd5855a49924 | BG21: Июнь | BH21: 148972 | BI21: 54539 | BJ21: prtr9jqee | BK21: 684 | BR21: 18 | BS21: prtr9jqee | BT21: 148972 | BU21: 54539 | BV21: 684 | BW21: =IF(BS21=$CA$12,COUNTIF($BS$4:BS21,$CA$12),"") -> 6
E22: 19 | F22: 2e36ca7b21d3 | G22: prtr9jqee | H22: Июль | I22: 148424 | J22: 50550 | K22: 2496 | AW22: 69d3f00ee89c | AX22: =VLOOKUP(VLOOKUP(AW22,CHOOSE({1,2},BF:BF,BJ:BJ),2,0),BB:BC,2,0) -> FinEdge Solutions (FES) | BB22: prtrap61y | BC22: FinKey Dynamics | BE22: 19 | BF22: 2e36ca7b21d3 | BG22: Июль | BH22: 148424 | BI22: 50550 | BJ22: prtr9jqee | BK22: 2496 | BR22: 19 | BS22: prtr9jqee | BT22: 148424 | BU22: 50550 | BV22: 2496 | BW22: =IF(BS22=$CA$12,COUNTIF($BS$4:BS22,$CA$12),"") -> 7
E23: 20 | F23: 29778b3d3839 | G23: prtr9jqee | H23: Август | I23: 22001 | J23: 6365 | K23: 374 | AW23: 9a808c55a887 | AX23: =VLOOKUP(VLOOKUP(AW23,CHOOSE({1,2},BF:BF,BJ:BJ),2,0),BB:BC,2,0) -> DataFin Marketers (DFM) | BB23: prtr6is7y | BC23: PrimeMarketplace | BE23: 20 | BF23: 29778b3d3839 | BG23: Август | BH23: 22001 | BI23: 6365 | BJ23: prtr9jqee | BK23: 374 | BR23: 20 | BS23: prtr9jqee | BT23: 22001 | BU23: 6365 | BV23: 374 | BW23: =IF(BS23=$CA$12,COUNTIF($BS$4:BS23,$CA$12),"") -> 8
E24: 21 | F24: b90884d71b53 | G24: prtr9jqee | H24: Сентябрь | I24: 100226 | J24: 27633 | K24: 2725 | AW24: ff0d212eddce | AX24: =VLOOKUP(VLOOKUP(AW24,CHOOSE({1,2},BF:BF,BJ:BJ),2,0),BB:BC,2,0) -> MarketUp Pro | BB24: prtr5li23 | BC24: EcomWise Agency | BE24: 21 | BF24: b90884d71b53 | BG24: Сентябрь | BH24: 100226 | BI24: 27633 | BJ24: prtr9jqee | BK24: 2725 | BR24: 21 | BS24: prtr9jqee | BT24: 100226 | BU24: 27633 | BV24: 2725 | BW24: =IF(BS24=$CA$12,COUNTIF($BS$4:BS24,$CA$12),"") -> 9
... E33: 30 | F33: af82fca66ddf | G33: prtr5veu2 | H33: Июнь | I33: 53481 | J33: 15745 | K33: 775 | AW33: 50904ff0ee30 | AX33: =VLOOKUP(VLOOKUP(AW33,CHOOSE({1,2},BF:BF,BJ:BJ),2,0),BB:BC,2,0) -> FinGo Analytics | BB33: prtryfr9r | BC33: CoreMarket Dynamics | BE33: 30 | BF33: af82fca66ddf | BG33: Июнь | BH33: 53481 | BI33: 15745 | BJ33: prtr5veu2 | BK33: 775 | BR33: 30 | BS33: prtr5veu2 | BT33: 53481 | BU33: 15745 | BV33: 775 | BW33: =IF(BS33=$CA$12,COUNTIF($BS$4:BS33,$CA$12),"")
E34: 31 | F34: 7d2bfb3b8ccd | G34: prtr5veu2 | H34: Июль | I34: 71572 | J34: 14477 | K34: 1109 | BB34: prtrzv8wc | BC34: EcomSphere Labs | BE34: 31 | BF34: 7d2bfb3b8ccd | BG34: Июль | BH34: 71572 | BI34: 14477 | BJ34: prtr5veu2 | BK34: 1109 | BR34: 31 | BS34: prtr5veu2 | BT34: 71572 | BU34: 14477 | BV34: 1109 | BW34: =IF(BS34=$CA$12,COUNTIF($BS$4:BS34,$CA$12),"")
E35: 32 | F35: 8f47cc8df66d | G35: prtr5veu2 | H35: Август | I35: 15916 | J35: 3992 | K35: 19 | BB35: prtr18c9h | BC35: FinScale Strategies | BE35: 32 | BF35: 8f47cc8df66d | BG35: Август | BH35: 15916 | BI35: 3992 | BJ35: prtr5veu2 | BK35: 19 | BR35: 32 | BS35: prtr5veu2 | BT35: 15916 | BU35: 3992 | BV35: 19 | BW35: =IF(BS35=$CA$12,COUNTIF($BS$4:BS35,$CA$12),"")
E36: 33 | F36: e513e5acc113 | G36: prtr5veu2 | H36: Сентябрь | I36: 133358 | J36: 40316 | K36: 3830 | BB36: prtrt39ag | BC36: Boostify Marketplace | BE36: 33 | BF36: e513e5acc113 | BG36: Сентябрь | BH36: 133358 | BI36: 40316 | BJ36: prtr5veu2 | BK36: 3830 | BR36: 33 | BS36: prtr5veu2 | BT36: 133358 | BU36: 40316 | BV36: 3830 | BW36: =IF(BS36=$CA$12,COUNTIF($BS$4:BS36,$CA$12),"")
E37: 34 | F37: c0d5d5e67bfb | G37: prtr5veu2 | H37: Октябрь | I37: 146932 | J37: 45905 | K37: 4101 | BB37: prtrxtdf1 | BC37: PaySecure Systems (PSS) | BE37: 34 | BF37: c0d5d5e67bfb | BG37: Октябрь | BH37: 146932 | BI37: 45905 | BJ37: prtr5veu2 | BK37: 4101 | BR37: 34 | BS37: prtr5veu2 | BT37: 146932 | BU37: 45905 | BV37: 4101 | BW37: =IF(BS37=$CA$12,COUNTIF($BS$4:BS37,$CA$12),"")
E38: 35 | F38: e206f447810e | G38: prtr5veu2 | H38: Ноябрь | I38: 18678 | J38: 5223 | K38: 374 | BB38: prtr6jph3 | BC38: EcoFin Nexus (EFN) | BE38: 35 | BF38: e206f447810e | BG38: Ноябрь | BH38: 18678 | BI38: 5223 | BJ38: prtr5veu2 | BK38: 374 | BR38: 35 | BS38: prtr5veu2 | BT38: 18678 | BU38: 5223 | BV38: 374 | BW38: =IF(BS38=$CA$12,COUNTIF($BS$4:BS38,$CA$12),"")
E39: 36 | F39: 51d7eac6f56d | G39: prtr5veu2 | H39: Декабрь | I39: 119531 | J39: 33160 | K39: 2030 | BB39: prtr00z3s | BC39: EcomTrail Partners | BE39: 36 | BF39: 51d7eac6f56d | BG39: Декабрь | BH39: 119531 | BI39: 33160 | BJ39: prtr5veu2 | BK39: 2030 | BR39: 36 | BS39: prtr5veu2 | BT39: 119531 | BU39: 33160 | BV39: 2030 | BW39: =IF(BS39=$CA$12,COUNTIF($BS$4:BS39,$CA$12),"")
E40: 37 | F40: f1d4ef483c1e | G40: prtrczb25 | H40: Январь | I40: 97983 | J40: 23779 | K40: 443 | BB40: prtrx2dwv | BC40: FinLink Innovations | BE40: 37 | BF40: f1d4ef483c1e | BG40: Январь | BH40: 97983 | BI40: 23779 | BJ40: prtrczb25 | BK40: 443 | BR40: 37 | BS40: prtrczb25 | BT40: 97983 | BU40: 23779 | BV40: 443 | BW40: =IF(BS40=$CA$12,COUNTIF($BS$4:BS40,$CA$12),"")
E41: 38 | F41: 102bec00f3e6 | G41: prtrczb25 | H41: Февраль | I41: 20916 | J41: 6503 | K41: 283 | BB41: prtr701wd | BC41: OmniMarket Pro | BE41: 38 | BF41: 102bec00f3e6 | BG41: Февраль | BH41: 20916 | BI41: 6503 | BJ41: prtrczb25 | BK41: 283 | BR41: 38 | BS41: prtrczb25 | BT41: 20916 | BU41: 6503 | BV41: 283 | BW41: =IF(BS41=$CA$12,COUNTIF($BS$4:BS41,$CA$12),"")
E42: 39 | F42: 3a3aaea5785b | G42: prtrczb25 | H42: Март | I42: 85691 | J42: 21208 | K42: 1513 | BB42: prtrxih4w | BC42: TechFin Studio | BE42: 39 | BF42: 3a3aaea5785b | BG42: Март | BH42: 85691 | BI42: 21208 | BJ42: prtrczb25 | BK42: 1513 | BR42: 39 | BS42: prtrczb25 | BT42: 85691 | BU42: 21208 | BV42: 1513 | BW42: =IF(BS42=$CA$12,COUNTIF($BS$4:BS42,$CA$12),"")
E43: 40 | F43: 60300685f57f | G43: prtrczb25 | H43: Апрель | I43: 50252 | J43: 16247 | K43: 987 | BB43: prtrb4y7e | BC43: MarketAlign Strategies | BE43: 40 | BF43: 60300685f57f | BG43: Апрель | BH43: 50252 | BI43: 16247 | BJ43: prtrczb25 | BK43: 987 | BR43: 40 | BS43: prtrczb25 | BT43: 50252 | BU43: 16247 | BV43: 987 | BW43: =IF(BS43=$CA$12,COUNTIF($BS$4:BS43,$CA$12),"")
E44: 41 | F44: 22a59c15203c | G44: prtrczb25 | H44: Май | I44: 88951 | J44: 24212 | K44: 465 | BB44: prtr22ttc | BC44: FinBoost Systems | BE44: 41 | BF44: 22a59c15203c | BG44: Май | BH44: 88951 | BI44: 24212 | BJ44: prtrczb25 | BK44: 465 | BR44: 41 | BS44: prtrczb25 | BT44: 88951 | BU44: 24212 | BV44: 465 | BW44: =IF(BS44=$CA$12,COUNTIF($BS$4:BS44,$CA$12),"")
E45: 42 | F45: 3584a972f778 | G45: prtrczb25 | H45: Июнь | I45: 48313 | J45: 17942 | K45: 1351 | BB45: prtriraoa | BC45: EcomOptics Agency | BE45: 42 | BF45: 3584a972f778 | BG45: Июнь | BH45: 48313 | BI45: 17942 | BJ45: prtrczb25 | BK45: 1351 | BR45: 42 | BS45: prtrczb25 | BT45: 48313 | BU45: 17942 | BV45: 1351 | BW45: =IF(BS45=$CA$12,COUNTIF($BS$4:BS45,$CA$12),"")
... E53: 50 | F53: 663ff4f63e3b | G53: prtrmec8l | H53: Февраль | I53: 20830 | J53: 7760 | K53: 583 | BB53: prtr4p7x8 | BC53: PayWave Solutions | BE53: 50 | BF53: 663ff4f63e3b | BG53: Февраль | BH53: 20830 | BI53: 7760 | BJ53: prtrmec8l | BK53: 583 | BR53: 50 | BS53: prtrmec8l | BT53: 20830 | BU53: 7760 | BV53: 583 | BW53: =IF(BS53=$CA$12,COUNTIF($BS$4:BS53,$CA$12),"")
E54: 51 | F54: 572b13a37d6b | G54: prtrmec8l | H54: Март | I54: 35400 | J54: 7900 | K54: 135 | BE54: 51 | BF54: 572b13a37d6b | BG54: Март | BH54: 35400 | BI54: 7900 | BJ54: prtrmec8l | BK54: 135 | BR54: 51 | BS54: prtrmec8l | BT54: 35400 | BU54: 7900 | BV54: 135 | BW54: =IF(BS54=$CA$12,COUNTIF($BS$4:BS54,$CA$12),"")
E55: 52 | F55: 3d798328e02d | G55: prtrmec8l | H55: Апрель | I55: 46970 | J55: 17848 | K55: 270 | BE55: 52 | BF55: 3d798328e02d | BG55: Апрель | BH55: 46970 | BI55: 17848 | BJ55: prtrmec8l | BK55: 270 | BR55: 52 | BS55: prtrmec8l | BT55: 46970 | BU55: 17848 | BV55: 270 | BW55: =IF(BS55=$CA$12,COUNTIF($BS$4:BS55,$CA$12),"")
E56: 53 | F56: 9dae15b5e6dd | G56: prtrmec8l | H56: Май | I56: 90960 | J56: 25720 | K56: 1379 | BE56: 53 | BF56: 9dae15b5e6dd | BG56: Май | BH56: 90960 | BI56: 25720 | BJ56: prtrmec8l | BK56: 1379 | BR56: 53 | BS56: prtrmec8l | BT56: 90960 | BU56: 25720 | BV56: 1379 | BW56: =IF(BS56=$CA$12,COUNTIF($BS$4:BS56,$CA$12),"")
E57: 54 | F57: b561baccc615 | G57: prtrmec8l | H57: Июнь | I57: 36191 | J57: 14233 | K57: 1327 | BE57: 54 | BF57: b561baccc615 | BG57: Июнь | BH57: 36191 | BI57: 14233 | BJ57: prtrmec8l | BK57: 1327 | BR57: 54 | BS57: prtrmec8l | BT57: 36191 | BU57: 14233 | BV57: 1327 | BW57: =IF(BS57=$CA$12,COUNTIF($BS$4:BS57,$CA$12),"")
...

Sheet Справка
D7: Синтаксис и применение функций ссылок и массивов из официального источника
