Workbook
Name Срез_Месяц: #N/A

Sheet Тема урока
A32: 1
A66: 1
A99: 1

Sheet Выполнить
AA5: Месяц | AB5: Просмотры | AC5: Клики | AD5: Транзакции
AA6: Январь | AB6: 1027 | AC6: 1015 | AD6: 1314 | AG6: Месяц | AH6: Октябрь | BG6: Месяц | BH6: Просмотры | BI6: Клики | BJ6: Транзакции
AA7: Февраль | AB7: 1254 | AC7: 1193 | AD7: 1317 | AG7: Метрика | AH7: Транзакции | BG7: Январь | BH7: =SUMIFS(Отчет!AI:AI,Отчет!$AH:$AH,Выполнить!$BG7) -> 3828286 | BI7: =SUMIFS(Отчет!AJ:AJ,Отчет!$AH:$AH,Выполнить!$BG7) -> 1161053 | BJ7: =SUMIFS(Отчет!AK:AK,Отчет!$AH:$AH,Выполнить!$BG7) -> 49872 | BM7: Месяц | BN7: Июнь
F8: Месяц | G8: Просмотры | H8: Клики | I8: Транзакции | AA8: Март | AB8: 1429 | AC8: 1309 | AD8: 1418 | BG8: Февраль | BH8: =SUMIFS(Отчет!AI:AI,Отчет!$AH:$AH,Выполнить!$BG8) -> 4333553 | BI8: =SUMIFS(Отчет!AJ:AJ,Отчет!$AH:$AH,Выполнить!$BG8) -> 1339512 | BJ8: =SUMIFS(Отчет!AK:AK,Отчет!$AH:$AH,Выполнить!$BG8) -> 71742 | BM8: Метрика | BN8: Просмотры
F9: Январь | G9: =SUMIFS(Отчет!AI:AI,Отчет!$AH:$AH,Выполнить!$F9) -> 3828286 | H9: =SUMIFS(Отчет!AJ:AJ,Отчет!$AH:$AH,Выполнить!$F9) -> 1161053 | I9: =SUMIFS(Отчет!AK:AK,Отчет!$AH:$AH,Выполнить!$F9) -> 49872 | L9: Месяц | M9: Август | AA9: Апрель | AB9: 1345 | AC9: 1254 | AD9: 1080 | BG9: Март | BH9: =SUMIFS(Отчет!AI:AI,Отчет!$AH:$AH,Выполнить!$BG9) -> 3943674 | BI9: =SUMIFS(Отчет!AJ:AJ,Отчет!$AH:$AH,Выполнить!$BG9) -> 1154933 | BJ9: =SUMIFS(Отчет!AK:AK,Отчет!$AH:$AH,Выполнить!$BG9) -> 53544
F10: Февраль | G10: =SUMIFS(Отчет!AI:AI,Отчет!$AH:$AH,Выполнить!$F10) -> 4333553 | H10: =SUMIFS(Отчет!AJ:AJ,Отчет!$AH:$AH,Выполнить!$F10) -> 1339512 | I10: =SUMIFS(Отчет!AK:AK,Отчет!$AH:$AH,Выполнить!$F10) -> 71742 | L10: Метрика | M10: Транзакции | AA10: Май | AB10: 1061 | AC10: 1229 | AD10: 1047 | AG10: Результат | AH10: =INDEX($AB$6:$AD$17,MATCH($AH$6,$AA$6:$AA$17,0),MATCH($AH$7,$AB$5:$AD$5,0)) -> 1364 | BG10: Апрель | BH10: =SUMIFS(Отчет!AI:AI,Отчет!$AH:$AH,Выполнить!$BG10) -> 3537571 | BI10: =SUMIFS(Отчет!AJ:AJ,Отчет!$AH:$AH,Выполнить!$BG10) -> 1055719 | BJ10: =SUMIFS(Отчет!AK:AK,Отчет!$AH:$AH,Выполнить!$BG10) -> 53263
F11: Март | G11: =SUMIFS(Отчет!AI:AI,Отчет!$AH:$AH,Выполнить!$F11) -> 3943674 | H11: =SUMIFS(Отчет!AJ:AJ,Отчет!$AH:$AH,Выполнить!$F11) -> 1154933 | I11: =SUMIFS(Отчет!AK:AK,Отчет!$AH:$AH,Выполнить!$F11) -> 53544 | AA11: Июнь | AB11: 1100 | AC11: 1292 | AD11: 1035 | BG11: Май | BH11: =SUMIFS(Отчет!AI:AI,Отчет!$AH:$AH,Выполнить!$BG11) -> 3904801 | BI11: =SUMIFS(Отчет!AJ:AJ,Отчет!$AH:$AH,Выполнить!$BG11) -> 1142776 | BJ11: =SUMIFS(Отчет!AK:AK,Отчет!$AH:$AH,Выполнить!$BG11) -> 55983 | BM11: Результат | BN11: =INDEX($BG$6:$BJ$18,MATCH($BN$7,$BG$6:$BG$18,0),MATCH($BN$8,$BG$6:$BJ$6,0)) -> 3669099
F12: Апрель | G12: =SUMIFS(Отчет!AI:AI,Отчет!$AH:$AH,Выполнить!$F12) -> 3537571 | H12: =SUMIFS(Отчет!AJ:AJ,Отчет!$AH:$AH,Выполнить!$F12) -> 1055719 | I12: =SUMIFS(Отчет!AK:AK,Отчет!$AH:$AH,Выполнить!$F12) -> 53263 | AA12: Июль | AB12: 1377 | AC12: 1009 | AD12: 1466 | BG12: Июнь | BH12: =SUMIFS(Отчет!AI:AI,Отчет!$AH:$AH,Выполнить!$BG12) -> 3669099 | BI12: =SUMIFS(Отчет!AJ:AJ,Отчет!$AH:$AH,Выполнить!$BG12) -> 1107075 | BJ12: =SUMIFS(Отчет!AK:AK,Отчет!$AH:$AH,Выполнить!$BG12) -> 55813
F13: Май | G13: =SUMIFS(Отчет!AI:AI,Отчет!$AH:$AH,Выполнить!$F13) -> 3904801 | H13: =SUMIFS(Отчет!AJ:AJ,Отчет!$AH:$AH,Выполнить!$F13) -> 1142776 | I13: =SUMIFS(Отчет!AK:AK,Отчет!$AH:$AH,Выполнить!$F13) -> 55983 | L13: Результат | M13: =INDEX($F$8:$I$20,MATCH($M$9,$F$8:$F$20,0),MATCH($M$10,$F$8:$I$8,0)) -> 62505 | AA13: Август | AB13: 1077 | AC13: 1402 | AD13: 1144 | BG13: Июль | BH13: =SUMIFS(Отчет!AI:AI,Отчет!$AH:$AH,Выполнить!$BG13) -> 4067609 | BI13: =SUMIFS(Отчет!AJ:AJ,Отчет!$AH:$AH,Выполнить!$BG13) -> 1198712 | BJ13: =SUMIFS(Отчет!AK:AK,Отчет!$AH:$AH,Выполнить!$BG13) -> 52300
F14: Июнь | G14: =SUMIFS(Отчет!AI:AI,Отчет!$AH:$AH,Выполнить!$F14) -> 3669099 | H14: =SUMIFS(Отчет!AJ:AJ,Отчет!$AH:$AH,Выполнить!$F14) -> 1107075 | I14: =SUMIFS(Отчет!AK:AK,Отчет!$AH:$AH,Выполнить!$F14) -> 55813 | AA14: Сентябрь | AB14: 1314 | AC14: 1320 | AD14: 1024 | BG14: Август | BH14: =SUMIFS(Отчет!AI:AI,Отчет!$AH:$AH,Выполнить!$BG14) -> 4098500 | BI14: =SUMIFS(Отчет!AJ:AJ,Отчет!$AH:$AH,Выполнить!$BG14) -> 1320638 | BJ14: =SUMIFS(Отчет!AK:AK,Отчет!$AH:$AH,Выполнить!$BG14) -> 62505
F15: Июль | G15: =SUMIFS(Отчет!AI:AI,Отчет!$AH:$AH,Выполнить!$F15) -> 4067609 | H15: =SUMIFS(Отчет!AJ:AJ,Отчет!$AH:$AH,Выполнить!$F15) -> 1198712 | I15: =SUMIFS(Отчет!AK:AK,Отчет!$AH:$AH,Выполнить!$F15) -> 52300 | AA15: Октябрь | AB15: 1255 | AC15: 1391 | AD15: 1364 | BG15: Сентябрь | BH15: =SUMIFS(Отчет!AI:AI,Отчет!$AH:$AH,Выполнить!$BG15) -> 4001152 | BI15: =SUMIFS(Отчет!AJ:AJ,Отчет!$AH:$AH,Выполнить!$BG15) -> 1203579 | BJ15: =SUMIFS(Отчет!AK:AK,Отчет!$AH:$AH,Выполнить!$BG15) -> 63229
F16: Август | G16: =SUMIFS(Отчет!AI:AI,Отчет!$AH:$AH,Выполнить!$F16) -> 4098500 | H16: =SUMIFS(Отчет!AJ:AJ,Отчет!$AH:$AH,Выполнить!$F16) -> 1320638 | I16: =SUMIFS(Отчет!AK:AK,Отчет!$AH:$AH,Выполнить!$F16) -> 62505 | AA16: Ноябрь | AB16: 1407 | AC16: 1177 | AD16: 1176 | BG16: Октябрь | BH16: =SUMIFS(Отчет!AI:AI,Отчет!$AH:$AH,Выполнить!$BG16) -> 4338209 | BI16: =SUMIFS(Отчет!AJ:AJ,Отчет!$AH:$AH,Выполнить!$BG16) -> 1304043 | BJ16: =SUMIFS(Отчет!AK:AK,Отчет!$AH:$AH,Выполнить!$BG16) -> 60297
F17: Сентябрь | G17: =SUMIFS(Отчет!AI:AI,Отчет!$AH:$AH,Выполнить!$F17) -> 4001152 | H17: =SUMIFS(Отчет!AJ:AJ,Отчет!$AH:$AH,Выполнить!$F17) -> 1203579 | I17: =SUMIFS(Отчет!AK:AK,Отчет!$AH:$AH,Выполнить!$F17) -> 63229 | AA17: Декабрь | AB17: 1016 | AC17: 1364 | AD17: 1198 | BG17: Ноябрь | BH17: =SUMIFS(Отчет!AI:AI,Отчет!$AH:$AH,Выполнить!$BG17) -> 3681441 | BI17: =SUMIFS(Отчет!AJ:AJ,Отчет!$AH:$AH,Выполнить!$BG17) -> 1101239 | BJ17: =SUMIFS(Отчет!AK:AK,Отчет!$AH:$AH,Выполнить!$BG17) -> 48764
F18: Октябрь | G18: =SUMIFS(Отчет!AI:AI,Отчет!$AH:$AH,Выполнить!$F18) -> 4338209 | H18: =SUMIFS(Отчет!AJ:AJ,Отчет!$AH:$AH,Выполнить!$F18) -> 1304043 | I18: =SUMIFS(Отчет!AK:AK,Отчет!$AH:$AH,Выполнить!$F18) -> 60297 | BG18: Декабрь | BH18: =SUMIFS(Отчет!AI:AI,Отчет!$AH:$AH,Выполнить!$BG18) -> 3781474 | BI18: =SUMIFS(Отчет!AJ:AJ,Отчет!$AH:$AH,Выполнить!$BG18) -> 1056721 | BJ18: =SUMIFS(Отчет!AK:AK,Отчет!$AH:$AH,Выполнить!$BG18) -> 43937
F19: Ноябрь | G19: =SUMIFS(Отчет!AI:AI,Отчет!$AH:$AH,Выполнить!$F19) -> 3681441 | H19: =SUMIFS(Отчет!AJ:AJ,Отчет!$AH:$AH,Выполнить!$F19) -> 1101239 | I19: =SUMIFS(Отчет!AK:AK,Отчет!$AH:$AH,Выполнить!$F19) -> 48764
F20: Декабрь | G20: =SUMIFS(Отчет!AI:AI,Отчет!$AH:$AH,Выполнить!$F20) -> 3781474 | H20: =SUMIFS(Отчет!AJ:AJ,Отчет!$AH:$AH,Выполнить!$F20) -> 1056721 | I20: =SUMIFS(Отчет!AK:AK,Отчет!$AH:$AH,Выполнить!$F20) -> 43937

Sheet Отчет
F3: id_cmpgn | G3: id_prtr | H3: Месяц | I3: Просмотры | J3: Клики | K3: Транзакции | AJ3: Просмотры | AK3: Клики | AL3: Транзакции
E4: 1 | F4: 7536deca309a | G4: prtrjg8mf | H4: Январь | I4: 148483 | J4: 33258 | K4: 2834 | AJ4: =MAX(mark_tbl[[#All],[Просмотры]]) -> 47185369 | AK4: =MAX(mark_tbl[[#All],[Клики]]) -> 14146000 | AL4: =MAX(mark_tbl[[#All],[Транзакции]]) -> 671249
E5: 2 | F5: d1aaa9bf0482 | G5: prtrjg8mf | H5: Февраль | I5: 38241 | J5: 8823 | K5: 813
E6: 3 | F6: 96afc95efd12 | G6: prtrjg8mf | H6: Март | I6: 54157 | J6: 11297 | K6: 711
E7: 4 | F7: e9833306f49b | G7: prtrjg8mf | H7: Апрель | I7: 22200 | J7: 6717 | K7: 392
E8: 5 | F8: f3df42649379 | G8: prtrjg8mf | H8: Май | I8: 138053 | J8: 53787 | K8: 2795
E9: 6 | F9: fea36b22c7f4 | G9: prtrjg8mf | H9: Июнь | I9: 47567 | J9: 18717 | K9: 1418
E10: 7 | F10: 39fe9812bfb2 | G10: prtrjg8mf | H10: Июль | I10: 110416 | J10: 33701 | K10: 3266
E11: 8 | F11: 26b9f2986f37 | G11: prtrjg8mf | H11: Август | I11: 129454 | J11: 30877 | K11: 1029
E12: 9 | F12: 7cfcb4c3115e | G12: prtrjg8mf | H12: Сентябрь | I12: 109685 | J12: 40483 | K12: 3520 | AE12: # | AF12: id_cmpgn | AG12: id_prtr | AH12: Месяц | AI12: Просмотры | AJ12: Клики | AK12: Транзакции
E13: 10 | F13: 81e231fccb15 | G13: prtrjg8mf | H13: Октябрь | I13: 134341 | J13: 44339 | K13: 1025 | AE13: 1 | AF13: 7536deca309a | AG13: prtrjg8mf | AH13: Январь | AI13: 148483 | AJ13: 33258 | AK13: 2834
E14: 11 | F14: 44026375c796 | G14: prtrjg8mf | H14: Ноябрь | I14: 18425 | J14: 4724 | K14: 36 | AE14: 2 | AF14: d1aaa9bf0482 | AG14: prtrjg8mf | AH14: Февраль | AI14: 38241 | AJ14: 8823 | AK14: 813
E15: 12 | F15: 5fe6b74bb508 | G15: prtrjg8mf | H15: Декабрь | I15: 142027 | J15: 42175 | K15: 2193 | AE15: 3 | AF15: 96afc95efd12 | AG15: prtrjg8mf | AH15: Март | AI15: 54157 | AJ15: 11297 | AK15: 711
E16: 13 | F16: 615eaaebbc6c | G16: prtr9jqee | H16: Январь | I16: 110170 | J16: 36391 | K16: 2518 | AE16: 4 | AF16: e9833306f49b | AG16: prtrjg8mf | AH16: Апрель | AI16: 22200 | AJ16: 6717 | AK16: 392
E17: 14 | F17: ff9070b12c6f | G17: prtr9jqee | H17: Февраль | I17: 98498 | J17: 33414 | K17: 1572 | AE17: 5 | AF17: f3df42649379 | AG17: prtrjg8mf | AH17: Май | AI17: 138053 | AJ17: 53787 | AK17: 2795
E18: 15 | F18: b27746d730de | G18: prtr9jqee | H18: Март | I18: 86199 | J18: 26042 | K18: 70 | AE18: 6 | AF18: fea36b22c7f4 | AG18: prtrjg8mf | AH18: Июнь | AI18: 47567 | AJ18: 18717 | AK18: 1418
E19: 16 | F19: 078d4fa15ab6 | G19: prtr9jqee | H19: Апрель | I19: 131527 | J19: 40252 | K19: 2316 | AE19: 7 | AF19: 39fe9812bfb2 | AG19: prtrjg8mf | AH19: Июль | AI19: 110416 | AJ19: 33701 | AK19: 3266
E20: 17 | F20: 8814b359d5d8 | G20: prtr9jqee | H20: Май | I20: 13856 | J20: 5067 | K20: 256 | AE20: 8 | AF20: 26b9f2986f37 | AG20: prtrjg8mf | AH20: Август | AI20: 129454 | AJ20: 30877 | AK20: 1029
E21: 18 | F21: bd5855a49924 | G21: prtr9jqee | H21: Июнь | I21: 148972 | J21: 54539 | K21: 684 | AE21: 9 | AF21: 7cfcb4c3115e | AG21: prtrjg8mf | AH21: Сентябрь | AI21: 109685 | AJ21: 40483 | AK21: 3520
E22: 19 | F22: 2e36ca7b21d3 | G22: prtr9jqee | H22: Июль | I22: 148424 | J22: 50550 | K22: 2496 | AE22: 10 | AF22: 81e231fccb15 | AG22: prtrjg8mf | AH22: Октябрь | AI22: 134341 | AJ22: 44339 | AK22: 1025
E23: 20 | F23: 29778b3d3839 | G23: prtr9jqee | H23: Август | I23: 22001 | J23: 6365 | K23: 374 | AE23: 11 | AF23: 44026375c796 | AG23: prtrjg8mf | AH23: Ноябрь | AI23: 18425 | AJ23: 4724 | AK23: 36
E24: 21 | F24: b90884d71b53 | G24: prtr9jqee | H24: Сентябрь | I24: 100226 | J24: 27633 | K24: 2725 | AE24: 12 | AF24: 5fe6b74bb508 | AG24: prtrjg8mf | AH24: Декабрь | AI24: 142027 | AJ24: 42175 | AK24: 2193
... E261: 258 | F261: 98541e947f3e | G261: prtrq48d6 | H261: Июнь | I261: 85627 | J261: 26284 | K261: 1572 | AE261: 249 | AF261: 04af38cdf3ed | AG261: prtr5li23 | AH261: Сентябрь | AI261: 99138 | AJ261: 32671 | AK261: 2591
E262: 259 | F262: 131346464827 | G262: prtrq48d6 | H262: Июль | I262: 40446 | J262: 8475 | K262: 589 | AE262: 250 | AF262: 7ade8916d5f8 | AG262: prtr5li23 | AH262: Октябрь | AI262: 98203 | AJ262: 33675 | AK262: 2361
E263: 260 | F263: 2d5fcf4add20 | G263: prtrq48d6 | H263: Август | I263: 128202 | J263: 47695 | K263: 1917 | AE263: 251 | AF263: c650b223c70f | AG263: prtr5li23 | AH263: Ноябрь | AI263: 86547 | AJ263: 28474 | AK263: 1843
E264: 261 | F264: 40cbae7ecb07 | G264: prtrq48d6 | H264: Сентябрь | I264: 103803 | J264: 32999 | K264: 1742 | AE264: 252 | AF264: 43d25410e413 | AG264: prtr5li23 | AH264: Декабрь | AI264: 135894 | AJ264: 33780 | AK264: 2008
E265: 262 | F265: 735503534afc | G265: prtrq48d6 | H265: Октябрь | I265: 137073 | J265: 49982 | K265: 647 | AE265: 253 | AF265: b9237cc57ce8 | AG265: prtrq48d6 | AH265: Январь | AI265: 99675 | AJ265: 29642 | AK265: 124
E266: 263 | F266: 571aba63c1c5 | G266: prtrq48d6 | H266: Ноябрь | I266: 85712 | J266: 21229 | K266: 1382 | AE266: 254 | AF266: 8e773aaad328 | AG266: prtrq48d6 | AH266: Февраль | AI266: 83694 | AJ266: 21543 | AK266: 133
E267: 264 | F267: c71825fa72a1 | G267: prtrq48d6 | H267: Декабрь | I267: 55117 | J267: 20733 | K267: 1216 | AE267: 255 | AF267: 5989505a0283 | AG267: prtrq48d6 | AH267: Март | AI267: 65520 | AJ267: 23883 | AK267: 1249
E268: 265 | F268: 83f9b73408dd | G268: prtrsyyx1 | H268: Январь | I268: 84981 | J268: 30858 | K268: 76 | AE268: 256 | AF268: d64d2f9de9b8 | AG268: prtrq48d6 | AH268: Апрель | AI268: 132632 | AJ268: 38951 | AK268: 821
E269: 266 | F269: 04a5817aa96b | G269: prtrsyyx1 | H269: Февраль | I269: 42256 | J269: 14032 | K269: 1049 | AE269: 257 | AF269: 4f84dbe73e58 | AG269: prtrq48d6 | AH269: Май | AI269: 65031 | AJ269: 17570 | AK269: 1317
E270: 267 | F270: 50904ff0ee30 | G270: prtrsyyx1 | H270: Март | I270: 114328 | J270: 30204 | K270: 2154 | AE270: 258 | AF270: 98541e947f3e | AG270: prtrq48d6 | AH270: Июнь | AI270: 85627 | AJ270: 26284 | AK270: 1572
E271: 268 | F271: 0f0db08ef840 | G271: prtrsyyx1 | H271: Апрель | I271: 93546 | J271: 28451 | K271: 462 | AE271: 259 | AF271: 131346464827 | AG271: prtrq48d6 | AH271: Июль | AI271: 40446 | AJ271: 8475 | AK271: 589
E272: 269 | F272: 513f9e16a72e | G272: prtrsyyx1 | H272: Май | I272: 123554 | J272: 26047 | K272: 1004 | AE272: 260 | AF272: 2d5fcf4add20 | AG272: prtrq48d6 | AH272: Август | AI272: 128202 | AJ272: 47695 | AK272: 1917
E273: 270 | F273: 24831c9c328f | G273: prtrsyyx1 | H273: Июнь | I273: 36450 | J273: 12339 | K273: 806 | AE273: 261 | AF273: 40cbae7ecb07 | AG273: prtrq48d6 | AH273: Сентябрь | AI273: 103803 | AJ273: 32999 | AK273: 1742
E274: 271 | F274: 8cadc39c5f06 | G274: prtrsyyx1 | H274: Июль | I274: 131757 | J274: 31760 | K274: 1955 | AE274: 262 | AF274: 735503534afc | AG274: prtrq48d6 | AH274: Октябрь | AI274: 137073 | AJ274: 49982 | AK274: 647
E275: 272 | F275: 56cda223ccf7 | G275: prtrsyyx1 | H275: Август | I275: 120588 | J275: 45491 | K275: 3315 | AE275: 263 | AF275: 571aba63c1c5 | AG275: prtrq48d6 | AH275: Ноябрь | AI275: 85712 | AJ275: 21229 | AK275: 1382
E276: 273 | F276: 0735a0d73046 | G276: prtrsyyx1 | H276: Сентябрь | I276: 75594 | J276: 26419 | K276: 1244 | AE276: 264 | AF276: c71825fa72a1 | AG276: prtrq48d6 | AH276: Декабрь | AI276: 55117 | AJ276: 20733 | AK276: 1216
E277: 274 | F277: 560209e462de | G277: prtrsyyx1 | H277: Октябрь | I277: 53691 | J277: 17445 | K277: 455 | AE277: 265 | AF277: 83f9b73408dd | AG277: prtrsyyx1 | AH277: Январь | AI277: 84981 | AJ277: 30858 | AK277: 76
E278: 275 | F278: 9e19c4a14337 | G278: prtrsyyx1 | H278: Ноябрь | I278: 15697 | J278: 5771 | K278: 334 | AE278: 266 | AF278: 04a5817aa96b | AG278: prtrsyyx1 | AH278: Февраль | AI278: 42256 | AJ278: 14032 | AK278: 1049
...

Sheet Справка
D7: Синтаксис и применение функций ссылок и массивов из официального источника
